Workbook
Name EnterPrise: [1]Cadastro!#REF!
Name EnterPrise: [1]Cadastro!#REF!
Name EnterPrise: [1]Cadastro!#REF!
Name EnterPrise: [1]Cadastro!#REF!
Name EnterPrise: [1]Cadastro!#REF!
Name EnterPrise: [1]Cadastro!#REF!
Name EnterPrise: [1]Cadastro!#REF!
Name EnterPrise: [1]Cadastro!#REF!
Name EnterPrise: [1]Cadastro!#REF!
Name Gopal: [1]Cadastro!#REF!
Name Gopal: [1]Cadastro!#REF!
Name Gopal: [1]Cadastro!#REF!
Name Gopal: [1]Cadastro!#REF!
Name Gopal: [1]Cadastro!#REF!
Name Gopal: [1]Cadastro!#REF!
Name Gopal: [1]Cadastro!#REF!
Name Gopal: [1]Cadastro!#REF!
Name Gopal: [1]Cadastro!#REF!
Name Platô: [1]Cadastro!#REF!
Name Platô: [1]Cadastro!#REF!
Name Platô: [1]Cadastro!#REF!
Name Platô: [1]Cadastro!#REF!
Name Platô: [1]Cadastro!#REF!
Name Platô: [1]Cadastro!#REF!
Name Platô: [1]Cadastro!#REF!
Name Platô: [1]Cadastro!#REF!
Name Platô: [1]Cadastro!#REF!
Name RendimentoFVC: [1]Cadastro!#REF!
Name RendimentoFVC: [1]Cadastro!#REF!
Name RendimentoFVC: [1]Cadastro!#REF!
Name RendimentoFVC: [1]Cadastro!#REF!
Name RendimentoFVC: [1]Cadastro!#REF!
Name RendimentoFVC: [1]Cadastro!#REF!
Name RendimentoFVC: [1]Cadastro!#REF!
Name RendimentoFVC: [1]Cadastro!#REF!
Name RendimentoFVC: [1]Cadastro!#REF!
Name Touro: [1]Cadastro!#REF!
Name Touro: [1]Cadastro!#REF!
Name Touro: [1]Cadastro!#REF!
Name Touro: [1]Cadastro!#REF!
Name Touro: [1]Cadastro!#REF!
Name Touro: [1]Cadastro!#REF!
Name Touro: [1]Cadastro!#REF!
Name Touro: [1]Cadastro!#REF!
Name Touro: [1]Cadastro!#REF!

Sheet INICIO
C1: Estação de Monta de 2019/20
B3: LOTES | I3: MATRIZES | P3: LOTES
I5: ='CONTROLE LOTE'!D45 -> 384 | P5: =SUM(IFERROR(1/COUNTIF('CONTROLE LOTE'!B7:B44,'CONTROLE LOTE'!B7:B44),0)) -> 0
B6: HORÁRIO
I7: Qtde. matrizes na EM | P7: Qtde. lotes relacionados a EM
B9: PROTOCOLO | G9: HISTORICO | N9: VACINA REPRODUTIVA
B12: IMPLANTE
B15: SEMÊN | G15: ANÁLISE

Sheet CONTROLE LOTE
B2: Gestão de Lotes
B5: LOTES | C5: IMPLANTE - D0 | E5: MEDICAÇÃO - D7 | G5: RETIRADA - D8 | I5: RETIRADA - D9 | K5: IA - 10 | M5: IA - 11 | O5: DG | S5: OBSERVAÇÃO | U5: DATA - US
C6: DATA | D6: QTIDADE | E6: DATA | F6: QTIDADE | G6: DATA | H6: QTIDADE | I6: DATA | J6: QTIDADE | K6: DATA | L6: QTIDADE | M6: DATA | N6: QTIDADE | O6: DATA | P6: QTIDADE | Q6: PRENHES | R6: ÍNDICE
B7: 1 | C7: 45967 | D7: 29 | E7: 45967 | F7: 29 | G7: 45975 | H7: 29 | I7: 45977 | J7: 29 | M7: 45977 | N7: 29 | R7: =Q7/P7 -> #DIV/0! | S7: vermifugo e fos | U7: =K7+30 -> 30
B8: 2 | C8: 45967 | D8: 29 | E8: 45967 | F8: 29 | G8: 45975 | H8: 29 | I8: 45977 | J8: 29 | M8: 45977 | N8: 29 | R8: =Q8/P8 -> #DIV/0! | S8: vermifugo e fos | U8: =K8+30 -> 30
B9: 3 | C9: 45967 | D9: 87 | E9: 0.54545455 | F9: 88 | G9: 45975 | H9: 88 | I9: 45977 | J9: 88 | M9: 45977 | N9: 88 | R9: =Q9/P9 -> #DIV/0! | S9: parte lote pgf, vermif, fos | U9: =M9+30 -> 46007
B10: 4 | C10: 45993 | D10: 16 | G10: 46001 | H10: 16 | K10: 46003 | L10: 16 | R10: =Q10/P10 -> #DIV/0! | U10: =M10+30 -> 30
B11: 5 | C11: 45993 | D11: 48 | G11: 46001 | H11: 48 | K11: 46003 | L11: 48 | R11: =Q11/P11 -> #DIV/0! | U11: =M11+30 -> 30
B12: 1A | C12: 46387 | D12: 23 | I12: 46030 | J12: 23 | M12: 46032 | N12: 23 | R12: =Q12/P12 -> #DIV/0! | U12: =M12+30 -> 46062
B13: 2A | C13: 46387 | D13: 18 | I13: 46030 | J13: 18 | M13: 10 | N13: 18 | R13: =Q13/P13 -> #DIV/0! | U13: =M13+30 -> 40
B14: 3A | C14: 31 | D14: 54 | I14: 46030 | J14: 54 | M14: 10 | N14: 54 | R14: =Q14/P14 -> #DIV/0! | U14: =M14+30 -> 40
B15: 6 | C15: 46036 | D15: 80 | G15: 46044 | H15: 80 | K15: 46046 | R15: =Q15/P15 -> #DIV/0! | U15: =K15+30 -> 46076
R16: =Q16/P16 -> #DIV/0! | U16: =K16+30 -> 30
R17: =Q17/P17 -> #DIV/0! | U17: =K17+30 -> 30
R18: =Q18/P18 -> #DIV/0! | U18: =K18+30 -> 30
R19: =Q19/P19 -> #DIV/0! | U19: =M19+30 -> 30
R20: =Q20/P20 -> #DIV/0! | U20: =M20+30 -> 30
R21: =Q21/P21 -> #DIV/0! | U21: =M21+30 -> 30
R22: =Q22/P22 -> #DIV/0! | U22: =M22+30 -> 30
R23: =Q23/P23 -> #DIV/0! | U23: =M23+30 -> 30
R24: =Q24/P24 -> #DIV/0! | U24: =M24+30 -> 30
R25: =Q25/P25 -> #DIV/0! | U25: =M25+30 -> 30
R26: =Q26/P26 -> #DIV/0! | U26: =M26+30 -> 30
R27: =Q27/P27 -> #DIV/0! | U27: =M27+30 -> 30
R28: =Q28/P28 -> #DIV/0! | U28: =M28+30 -> 30
R29: =Q29/P29 -> #DIV/0! | U29: =M29+30 -> 30
R30: =Q30/P30 -> #DIV/0! | U30: =M30+30 -> 30
... R42: =Q42/P42 -> #DIV/0! | U42: =M42+30 -> 30
R43: =Q43/P43 -> #DIV/0!
R44: =Q44/P44 -> #DIV/0!
B45: TOTAL | D45: =SUM(D7:D44) -> 384 | F45: =SUM(F7:F44) -> 146 | H45: =SUM(H7:H44) -> 290 | J45: =SUM(J7:J44) -> 241 | L45: =SUM(L7:L44) -> 64 | N45: =SUM(N7:N44) -> 241 | P45: =SUM(P7:P44) -> 0
K46: TOTAL | L46: =L45+N45 -> 305
J50: TOTAL | L50: =L48+L49 -> 0

Sheet CONTROLE HORARIO
B1: Gestão de Horário
B5: LOTES | C5: IMPLANTE - D0 | E5: MEDICAÇÃO - D7 | G5: RETIRADA - D8 | I5: RETIRADA - D9 | K5: IA - D10 | M5: IA - D11 | O5: OBSERVAÇÃO
C6: H. INICIAL | D6: H. FINAL | E6: H. INICIAL | F6: H. FINAL | G6: H. INICIAL | H6: H. FINAL | I6: H. INICIAL | J6: H. FINAL | K6: H. INICIAL | L6: H. FINAL | M6: H. INICIAL | N6: H. FINAL
B7: 1 | C7: 0.29791667 | D7: 0.3125 | G7: 0.65277778 | H7: 0.66319444 | K7: 0.6875 | L7: 0.70763889
B8: 2 | C8: 0.31597222 | D8: 0.34027778 | G8: 0.66458333 | H8: 0.67361111 | K8: 0.70833333 | L8: 0.72430556
B9: 3 | C9: 0.34722222 | D9: 0.40277778 | G9: 0.67708333 | H9: 0.70138889 | K9: 0.72916667 | L9: 0.76388889
B10: 4 | C10: 0.77777778 | D10: 0.79861111 | G10: 0.75 | H10: 0.76041667
B11: 5 | C11: 0.80208333 | D11: 0.82638889 | G11: 0.76388889 | H11: 0.78472222
B12: 1A | C12: 0.64583333 | D12: 0.66319444 | G12: 0.67013889 | H12: 0.6875 | K12: 0.67361111 | L12: 0.69444444
B13: 2A | C13: 0.66666667 | D13: 0.68055556 | G13: 0.69097222 | H13: 0.71041667 | K13: 0.69791667 | L13: 0.71875
B14: 3A | C14: 0.69791667 | D14: 0.72916667 | G14: 0.71527778 | H14: 0.74305556 | K14: 0.72569444 | L14: 0.76388889
B15: 6 | C15: 0.33333333 | D15: 0.38194444 | G15: 0.38888889 | H15: 0.43055556 | K15: 0.42986111

Sheet CONTROLE PROTOCOLO
B2: Gestão Protocolo
B5: LOTES | C5: D0 - IMPLANTE | I5: D7 - MEDICAÇÃO | K5: D8 - RETIRADA | Q5: D9 - RETIRADA
C6: IMPLANTE | D6: USO | E6: BENZOATO | F6: DOSE | G6: PGF | H6: DOSE | I6: PGF | J6: DOSE | K6: ESTROGINO | L6: DOSE | M6: PGF | N6: DOSE | O6: ECG | P6: DOSE | Q6: ESTROGINO | R6: DOSE | S6: PGF | T6: DOSE | U6: ECG | V6: DOSE
B7: 1 | C7: Repro Neo | D7: 1 | E7: Syncrogem | F7: 2 | K7: Cipion | L7: 0.5 | M7: Inducio | N7: 2 | O7: Ecgem | P7: 1.5
B8: 2 | C8: Repro Neo | D8: 1 | E8: Syncrogem | F8: 2 | G8: Inducio | H8: 2 | K8: Cipion | L8: 0.5 | M8: Inducio | N8: 2 | O8: Ecgem | P8: 1.5
B9: 3 | C9: Repro Neo | D9: 1 | E9: Syncrogem | F9: 2 | G9: Inducio | H9: 2 | K9: Cipion | L9: 0.5 | M9: Inducio | N9: 2 | O9: Ecgem | P9: 1.5
B10: 4 | C10: Repro Neo | D10: 2 | E10: Syncrogem | F10: 2 | K10: Cipion | L10: 0.5 | M10: Inducio | N10: 2 | O10: Ecgem | P10: 1.5
B11: 5 | C11: Repro Neo | D11: 2 | E11: Syncrogem | F11: 2 | K11: Cipion | L11: 0.5 | M11: Inducio | N11: 2 | O11: Ecgem | P11: 1.5
B12: 1A | C12: Repro Neo | D12: 3 | E12: Syncrogem | F12: 2 | K12: Cipion | L12: 0.5 | M12: Inducio | N12: 2 | O12: Ecgem | P12: 1.5
B13: 2A | C13: Repro Neo | D13: 3 | E13: Syncrogem | F13: 2 | K13: Cipion | L13: 0.5 | M13: Inducio | N13: 2 | O13: Ecgem | P13: 1.5
B14: 3A | C14: Repro Neo | D14: 3 | E14: Syncrogem | F14: 2 | K14: Cipion | L14: 0.5 | M14: Inducio | N14: 2 | O14: Ecgem | P14: 1.5
B15: 6 | C15: Repro Neo | D15: 1 | E15: Syncrogem | F15: 2

Sheet CONTROLE IMPLANTE
B1: Gestão de Implante
B4: LOTES | C4: RESPONSSAVEL | D4: QUANTIDADE | E4: EMPRESA | F4: CATEGORIA | G4: PERDA | H4: % PERDA | J4: OBSERVAÇÃO
B5: 1 | C5: Cezar | D5: 29 | E5: Globalgem | F5: Multípara | G5: 0 | H5: =G5/D5 -> 0
B6: 2 | C6: Cezar | D6: 29 | E6: Globalgem | F6: Novilhas | G6: 0 | H6: =G6/D6 -> 0
B7: 3 | C7: Cezar | D7: 88 | E7: Globalgem | F7: Solteiras | G7: 1 | H7: =G7/D7 -> 0.011363636
B8: 4 | C8: Cezar | D8: 16 | E8: Globalgem | F8: Novilhas | G8: 0 | H8: %
B9: 5 | C9: Cezar | D9: 48 | E9: Globalgem | F9: Multípara | G9: 0 | H9: =G9/D9 -> 0
B10: 1A | C10: Cezar | D10: 23 | E10: Globalgem | F10: Multípara | H10: =G10/D10 -> 0
B11: 2A | C11: Cezar | D11: 18 | E11: Globalgem | F11: Novilhas | H11: =G11/D11 -> 0
B12: 3A | C12: Cezar | D12: 54 | E12: Globalgem | F12: Solteiras | H12: =G12/D12 -> 0
B13: 6 | C13: Cezar | D13: 80 | E13: Globalgem | F13: Multípara | H13: =G13/D13 -> 0
H14: =G14/D14 -> #DIV/0!
H15: =G15/D15 -> #DIV/0!
H16: =G16/D16 -> #DIV/0!
H17: =G17/D17 -> #DIV/0!
H18: =G18/D18 -> #DIV/0!
H19: =G19/D19 -> #DIV/0!
H20: =G20/D20 -> #DIV/0!
H21: =G21/D21 -> #DIV/0!
H22: =G22/D22 -> #DIV/0!
H23: =G23/D23 -> #DIV/0!
H24: =G24/D24 -> #DIV/0!
H25: =G25/D25 -> #DIV/0!
... H93: =G93/D93 -> #DIV/0!
B94: TOTAL | D94: =SUM(D5:D93) -> 385 | G94: =SUM(G5:G93) -> 1 | H94: =G94/D94 -> 0.0025974026

Sheet CONTROLE SEMEN
B2: Gestão de Semên
B5: LOTE | C5: RESPONSSAVEL | D5: TOURO | E5: QUANTIDADE TOTAL | F5: PERDA | G5: % | H5: OBS.:
B7: 1 | C7: João V. Mazetto | D7: Guapo Zurita | E7: 12 | F7: 1 | G7: =F7/E7 -> 0.083333333
B8: 1 | C8: João V. Mazetto | D8: Vagalume | E8: 17 | G8: =F8/E8 -> 0
B9: 2 | C9: João V. Mazetto | D9: Guapo Zurita | E9: 3 | G9: =F9/E9 -> 0
B10: 2 | C10: João V. Mazetto | D10: Vagalume | E10: 26 | G10: =F10/E10 -> 0
B11: 3 | C11: João V. Mazetto | D11: Guapo Zurita | E11: 27 | G11: =F11/E11 -> 0
B12: 3 | C12: João V. Mazetto | D12: Vagalume | E12: 26 | G12: =F12/E12 -> 0
B13: 4 | C13: Marcela | D13: Guapo Zurita | E13: 8 | G13: =F13/E13 -> 0
B14: 4 | C14: Marcela | D14: Vagalume | E14: 9 | G14: =F14/E14 -> 0
B15: 5 | C15: Marcela | D15: Guapo Zurita | E15: 15 | F15: 2 | G15: =F15/E15 -> 0.13333333
B16: 5 | C16: Marcela | D16: Vagalume | E16: 32 | F16: 2 | G16: =F16/E16 -> 0.0625
B17: 1.A | C17: Luana | D17: Guapo Zurita | E17: 9 | G17: =F17/E17 -> 0
B18: 1.A | C18: Luana | D18: Vagalume | E18: 8 | G18: =F18/E18 -> 0
B19: 2.A | C19: Luana | D19: Guapo Zurita | E19: 2 | G19: =F19/E19 -> 0
B20: 2.A | C20: Luana | D20: Vagalume | E20: 10 | G20: =F20/E20 -> 0
B21: 3.A | C21: Luana | D21: Guapo Zurita | E21: 14 | G21: =F21/E21 -> 0
B22: 3.A | C22: Luana | D22: Vagalume | E22: 33 | G22: =F22/E22 -> 0
B23: 6 | C23: Cesar | D23: Guapo Zurita | E23: 19 | F23: 2 | G23: =F23/E23 -> 0.10526316
B24: 6 | C24: Cesar | D24: Vagalume | E24: 59 | F24: 3 | G24: =F24/E24 -> 0.050847458
G25: =F25/E25 -> #DIV/0!
G26: =F26/E26 -> #DIV/0!
G27: =F27/E27 -> #DIV/0!
G28: =F28/E28 -> #DIV/0!
G29: =F29/E29 -> #DIV/0!
G30: =F30/E30 -> #DIV/0!
G31: =F31/E31 -> #DIV/0!
G32: =F32/E32 -> #DIV/0!
G33: =F33/E33 -> #DIV/0!
G34: =F34/E34 -> #DIV/0!
G35: =F35/E35 -> #DIV/0!
G36: =F36/E36 -> #DIV/0!
... G103: =F103/E103 -> #DIV/0!
B104: TOTAL | E104: =SUM(E7:E103) -> 329 | F104: =SUM(F7:F103) -> 10 | G104: =F104/E104 -> 0.030395137
D107: Touro | E107: Total
D108: Guapo Zurita | E108: =SUM(E7,E9,E11,E13,E15,E17,E19,E21,E23) -> 109
D109: Vagalume | E109: =SUM(E8,E10,E12,E14,E16,E18,E20,E20,E22,E24) -> 230

Sheet ANALISE
B2: Análise da IATF
C5: ANIMAIS TRABALHADOS
C7: DISPOSITIVO (USO)
C9: DISPOSITIVO (PESPONSÁVEL)
C11: SEMÊN (RESPONSÁVEL)

Sheet Animais trabalhado
B2: Quantidade de Animais Trabalhados por Manejo
D5: MANEJO | G5: 1º IATF | I5: 2º IATF | K5: 3º IATF | M5: TOTAL
D6: IMPLANTE | G6: 210 | M6: =G6+I6+K6 -> 210
D7: APLICAÇÃO MEDICAMENTO | G7: 210
D8: RETIRADA | G8: 210 | M8: =G8+I8+K8 -> 210
D9: INSEMINAÇÃO | G9: 146 | M9: =G9+I9+K9 -> 146
D10: DIAGNÓSTICO | M10: =G10+I10+K10 -> 0

Sheet Analise por dispositivo (perca)
B2: Análise por Dispositivo (Usos)
C5: DISPOSITIVO | E5: IMPLANTADA | G5: PERDA | I5: TAXA DE PERCA | K5: DISTRIBUIÇÃO
C6: PRIMEIRO USO | E6: 146 | G6: 1 | I6: =G6/E6 -> 0.0068493151 | K6: =E6/E11 -> #VALUE!
C7: SEGUNDO USO | E7: 64 | G7: =SUMIF('CONTROLE IMPLANTE'!$E$5:$E$93,"MSD 2",'CONTROLE IMPLANTE'!$G$5:$G$93) -> 0 | I7: =G7/E7 -> 0 | K7: =E7/E11 -> #VALUE!
C8: TERCEIRO USO | E8: =SUMIF('CONTROLE IMPLANTE'!$E$5:$E$93,"MSD 3",'CONTROLE IMPLANTE'!$D$5:$D$93) -> 0 | G8: =SUMIF('CONTROLE IMPLANTE'!$E$5:$E$93,"MSD 3",'CONTROLE IMPLANTE'!$G$5:$G$93) -> 0 | I8: =G8/E8 -> #DIV/0! | K8: =E8/E11 -> #VALUE!
E9: =COUNTIFS('[2]DADOS DA IATF'!E$7:E$16406,C9,'[2]DADOS DA IATF'!R$7:R$16406,"X") -> #VALUE! | G9: =COUNTIFS('[2]DADOS DA IATF'!E$7:E$16406,C9,'[2]DADOS DA IATF'!K$7:K$16406,"PRENHA IA",'[2]DADOS DA IATF'!G$7:G$16406,"X")+COUNTIFS('[2]DADOS DA IATF'!E$7:E$16406,C9,'[2]DADOS DA IATF'!K$7:K$16406,"VAZIA",'[2]DADOS DA IATF'!G$7:G$16406,"X")+COUNTIFS('[2]DADOS DA IATF'!E$7:E$16406,C9,'[2]DADOS DA IATF'!K$7:K$16406,"SINCRONIZADA",'[2]DADOS DA IATF'!G$7:G$16406,"X") -> #VALUE! | I9: =COUNTIFS('[2]DADOS DA IATF'!E$7:E$16406,C9,'[2]DADOS DA IATF'!K$7:K$16406,"NÃO DG",'[2]DADOS DA IATF'!G$7:G$16406,"X") -> #VALUE!
E10: =COUNTIFS('[2]DADOS DA IATF'!E$7:E$16406,C10,'[2]DADOS DA IATF'!R$7:R$16406,"X") -> #VALUE! | G10: =COUNTIFS('[2]DADOS DA IATF'!E$7:E$16406,C10,'[2]DADOS DA IATF'!K$7:K$16406,"PRENHA IA",'[2]DADOS DA IATF'!G$7:G$16406,"X")+COUNTIFS('[2]DADOS DA IATF'!E$7:E$16406,C10,'[2]DADOS DA IATF'!K$7:K$16406,"VAZIA",'[2]DADOS DA IATF'!G$7:G$16406,"X")+COUNTIFS('[2]DADOS DA IATF'!E$7:E$16406,C10,'[2]DADOS DA IATF'!K$7:K$16406,"SINCRONIZADA",'[2]DADOS DA IATF'!G$7:G$16406,"X") -> #VALUE! | I10: =COUNTIFS('[2]DADOS DA IATF'!E$7:E$16406,C10,'[2]DADOS DA IATF'!K$7:K$16406,"NÃO DG",'[2]DADOS DA IATF'!G$7:G$16406,"X") -> #VALUE!
C11: TOTAL | E11: =SUM(E6:F10) -> #VALUE! | G11: =SUM(G6:H10) -> #VALUE! | I11: =SUM(I6:J10) -> #DIV/0! | K11: =SUM(K6:K11) -> #VALUE!

Sheet Analise por dispositivo (resp)
B2: Análise por Dispositivo (Responsável)
C5: DISPOSITIVO | E5: IMPLANTADA | G5: PERDA | I5: TAXA DE PERCA | K5: DISTRIBUIÇÃO
C6: ReproNeo | E6: 210 | G6: 1 | I6: =G6/E6 -> 0.0047619048 | K6: =E6/E11 -> #VALUE!
E7: =SUMIF('CONTROLE IMPLANTE'!$C$5:$C$93,"WILLIAN",'CONTROLE IMPLANTE'!$D$5:$D$93) -> 0 | G7: =SUMIF('CONTROLE IMPLANTE'!$C$5:$C$93,"WILLIAN",'CONTROLE IMPLANTE'!$G$5:$G$93) -> 0 | I7: =G7/E7 -> #DIV/0! | K7: =E7/E11 -> #VALUE!
E8: =SUMIF('CONTROLE IMPLANTE'!$C$5:$C$93,"CARLOS",'CONTROLE IMPLANTE'!$D$5:$D$93) -> 0 | G8: =SUMIF('CONTROLE IMPLANTE'!$C$5:$C$93,"CARLOS",'CONTROLE IMPLANTE'!$G$5:$G$93) -> 0 | I8: =G8/E8 -> #DIV/0! | K8: =E8/E11 -> #VALUE!
E9: =COUNTIFS('[2]DADOS DA IATF'!E$7:E$16406,C9,'[2]DADOS DA IATF'!R$7:R$16406,"X") -> #VALUE! | G9: =COUNTIFS('[2]DADOS DA IATF'!E$7:E$16406,C9,'[2]DADOS DA IATF'!K$7:K$16406,"PRENHA IA",'[2]DADOS DA IATF'!G$7:G$16406,"X")+COUNTIFS('[2]DADOS DA IATF'!E$7:E$16406,C9,'[2]DADOS DA IATF'!K$7:K$16406,"VAZIA",'[2]DADOS DA IATF'!G$7:G$16406,"X")+COUNTIFS('[2]DADOS DA IATF'!E$7:E$16406,C9,'[2]DADOS DA IATF'!K$7:K$16406,"SINCRONIZADA",'[2]DADOS DA IATF'!G$7:G$16406,"X") -> #VALUE! | I9: =COUNTIFS('[2]DADOS DA IATF'!E$7:E$16406,C9,'[2]DADOS DA IATF'!K$7:K$16406,"NÃO DG",'[2]DADOS DA IATF'!G$7:G$16406,"X") -> #VALUE!
E10: =COUNTIFS('[2]DADOS DA IATF'!E$7:E$16406,C10,'[2]DADOS DA IATF'!R$7:R$16406,"X") -> #VALUE! | G10: =COUNTIFS('[2]DADOS DA IATF'!E$7:E$16406,C10,'[2]DADOS DA IATF'!K$7:K$16406,"PRENHA IA",'[2]DADOS DA IATF'!G$7:G$16406,"X")+COUNTIFS('[2]DADOS DA IATF'!E$7:E$16406,C10,'[2]DADOS DA IATF'!K$7:K$16406,"VAZIA",'[2]DADOS DA IATF'!G$7:G$16406,"X")+COUNTIFS('[2]DADOS DA IATF'!E$7:E$16406,C10,'[2]DADOS DA IATF'!K$7:K$16406,"SINCRONIZADA",'[2]DADOS DA IATF'!G$7:G$16406,"X") -> #VALUE! | I10: =COUNTIFS('[2]DADOS DA IATF'!E$7:E$16406,C10,'[2]DADOS DA IATF'!K$7:K$16406,"NÃO DG",'[2]DADOS DA IATF'!G$7:G$16406,"X") -> #VALUE!
C11: TOTAL | E11: =SUM(E6:F10) -> #VALUE! | G11: =SUM(G6:H10) -> #VALUE! | I11: =SUM(I6:J10) -> #DIV/0! | K11: =SUM(K6:K11) -> #VALUE!

Sheet Relatorio de Matrizes 
A1: Ficha Relatório.
A5: Produtor: - Propriedade:
A6: Data: 22/03/2020 | M6: Hora início: | P6: Hora término:
A7: Observações: | F7: Os lotes foram feitos diagnosticos com 30 dias.
A10: Seq. | B10: Número da fêmea | G10: CATEGORIA | J10: RETIRO | K10: TOURO | M10: RAÇA | N10: DATA I.A | O10: DIAGNÓSTICO | Q10: DATA D.G | R10: MÊS P.P
A11: 001 | B11: =IF('Lote 01'!E2="Prenha",'Lote 01'!C2,"-") -> - | G11: =IF('Lote 01'!E2="Prenha",'Lote 01'!I2,"-") -> - | K11: =IF('Lote 01'!E2="Prenha",'Lote 01'!J2,"-") -> -
A12: 002 | B12: =IF('Lote 01'!E3="Prenha",'Lote 01'!C3,"-") -> - | G12: =IF('Lote 01'!E3="Prenha",'Lote 01'!I3,"-") -> - | K12: =IF('Lote 01'!E3="Prenha",'Lote 01'!J3,"-") -> -
A13: 003 | B13: =IF('Lote 01'!E4="Prenha",'Lote 01'!C4,"-") -> - | G13: =IF('Lote 01'!E4="Prenha",'Lote 01'!I4,"-") -> - | K13: =IF('Lote 01'!E4="Prenha",'Lote 01'!J4,"-") -> -
A14: 004 | B14: =IF('Lote 01'!E5="Prenha",'Lote 01'!C5,"-") -> - | G14: =IF('Lote 01'!E5="Prenha",'Lote 01'!I5,"-") -> - | K14: =IF('Lote 01'!E5="Prenha",'Lote 01'!J5,"-") -> -
A15: 005 | B15: =IF('Lote 01'!E6="Prenha",'Lote 01'!C6,"-") -> 1204 | G15: =IF('Lote 01'!E6="Prenha",'Lote 01'!I6,"-") -> 0 | K15: =IF('Lote 01'!E6="Prenha",'Lote 01'!J6,"-") -> Vagalume
A16: 006 | B16: =IF('Lote 01'!E7="Prenha",'Lote 01'!C7,"-") -> 1214 | G16: =IF('Lote 01'!E7="Prenha",'Lote 01'!I7,"-") -> 0 | K16: =IF('Lote 01'!E7="Prenha",'Lote 01'!J7,"-") -> Vagalume
A17: 007 | B17: =IF('Lote 01'!E8="Prenha",'Lote 01'!C8,"-") -> - | G17: =IF('Lote 01'!E8="Prenha",'Lote 01'!I8,"-") -> - | K17: =IF('Lote 01'!E8="Prenha",'Lote 01'!J8,"-") -> -
A18: 008 | B18: =IF('Lote 01'!E9="Prenha",'Lote 01'!C9,"-") -> - | G18: =IF('Lote 01'!E9="Prenha",'Lote 01'!I9,"-") -> - | K18: =IF('Lote 01'!E9="Prenha",'Lote 01'!J9,"-") -> -
A19: 009 | B19: =IF('Lote 01'!E10="Prenha",'Lote 01'!C10,"-") -> 1855 | G19: =IF('Lote 01'!E10="Prenha",'Lote 01'!I10,"-") -> 0 | K19: =IF('Lote 01'!E10="Prenha",'Lote 01'!J10,"-") -> Vagalume
A20: 010 | B20: =IF('Lote 01'!E11="Prenha",'Lote 01'!C11,"-") -> - | G20: =IF('Lote 01'!E11="Prenha",'Lote 01'!I11,"-") -> - | K20: =IF('Lote 01'!E11="Prenha",'Lote 01'!J11,"-") -> -
A21: 011 | B21: =IF('Lote 01'!E12="Prenha",'Lote 01'!C12,"-") -> - | G21: =IF('Lote 01'!E12="Prenha",'Lote 01'!I12,"-") -> - | K21: =IF('Lote 01'!E12="Prenha",'Lote 01'!J12,"-") -> -
A22: 012 | B22: =IF('Lote 01'!E13="Prenha",'Lote 01'!C13,"-") -> - | K22: =IF('Lote 01'!E13="Prenha",'Lote 01'!J13,"-") -> -
A23: 013 | B23: ='Lote 01'!C14 -> 1978 | K23: =IF('Lote 01'!E14="Prenha",'Lote 01'!J14,"-") -> -
A24: 014 | B24: ='Lote 01'!C15 -> 2069
A25: 015 | B25: ='Lote 01'!C16 -> 2139
A26: 016 | B26: ='Lote 01'!C17 -> 2177
A27: 017 | B27: ='Lote 01'!C18 -> 2244
A28: 018 | B28: ='Lote 01'!C19 -> 2246
A29: 019 | B29: ='Lote 01'!C20 -> 2255
A30: 020 | B30: ='Lote 01'!C21 -> 2557
A31: 021 | B31: ='Lote 01'!C22 -> 2564
A32: 022 | B32: ='Lote 01'!C23 -> 2606
A33: 023 | B33: ='Lote 01'!C24 -> 2681
A34: 024 | B34: ='Lote 01'!C25 -> 3100
A35: 025 | B35: ='Lote 01'!C26 -> 3112
... A411: 401 | B411: ='Lote 01'!C402 -> 0
A412: 402
A413: 403
A414: 404
A415: 405
A416: 406
A417: 407
A418: 408
A419: 409
A420: 410
...

Sheet Analise por semen (resp)
B2: Análise Semên (Responsável)
C5: DISPOSITIVO | E5: INSEMINADA | G5: PERDA | I5: TAXA DE PERCA | K5: DISTRIBUIÇÃO
E6: =SUMIF('CONTROLE SEMEN'!$C$7:$C$103,"joão",'CONTROLE SEMEN'!$E$7:$E$103) -> 0 | G6: =SUMIF('CONTROLE SEMEN'!$C$7:$C$103,"joão",'CONTROLE SEMEN'!$F$7:$F$103) -> 0 | I6: =G6/E6 -> #DIV/0! | K6: =E6/E11 -> #DIV/0!
E7: =SUMIF('CONTROLE SEMEN'!$C$7:$C$103,"willian",'CONTROLE SEMEN'!$E$7:$E$103) -> 0 | G7: =SUMIF('CONTROLE SEMEN'!$C$7:$C$103,"willian",'CONTROLE SEMEN'!$F$7:$F$103) -> 0 | I7: =G7/E7 -> #DIV/0! | K7: =E7/E11 -> #DIV/0!
E8: =SUMIF('CONTROLE SEMEN'!$C$7:$C$103,"carlos",'CONTROLE SEMEN'!$E$7:$E$103) -> 0 | G8: =SUMIF('CONTROLE SEMEN'!$C$7:$C$103,"carlos",'CONTROLE SEMEN'!$F$7:$F$103) -> 0 | I8: =G8/E8 -> #DIV/0! | K8: =E8/E11 -> #DIV/0!
E9: =SUMIF('CONTROLE SEMEN'!$C$7:$C$103,"joão",'CONTROLE SEMEN'!$E$7:$E$103) -> 0 | G9: =COUNTIFS('[2]DADOS DA IATF'!E$7:E$16406,C9,'[2]DADOS DA IATF'!K$7:K$16406,"PRENHA IA",'[2]DADOS DA IATF'!G$7:G$16406,"X")+COUNTIFS('[2]DADOS DA IATF'!E$7:E$16406,C9,'[2]DADOS DA IATF'!K$7:K$16406,"VAZIA",'[2]DADOS DA IATF'!G$7:G$16406,"X")+COUNTIFS('[2]DADOS DA IATF'!E$7:E$16406,C9,'[2]DADOS DA IATF'!K$7:K$16406,"SINCRONIZADA",'[2]DADOS DA IATF'!G$7:G$16406,"X") -> #VALUE! | I9: =COUNTIFS('[2]DADOS DA IATF'!E$7:E$16406,C9,'[2]DADOS DA IATF'!K$7:K$16406,"NÃO DG",'[2]DADOS DA IATF'!G$7:G$16406,"X") -> #VALUE!
E10: =SUMIF('CONTROLE SEMEN'!$C$7:$C$103,"joão",'CONTROLE SEMEN'!$E$7:$E$103) -> 0 | G10: =COUNTIFS('[2]DADOS DA IATF'!E$7:E$16406,C10,'[2]DADOS DA IATF'!K$7:K$16406,"PRENHA IA",'[2]DADOS DA IATF'!G$7:G$16406,"X")+COUNTIFS('[2]DADOS DA IATF'!E$7:E$16406,C10,'[2]DADOS DA IATF'!K$7:K$16406,"VAZIA",'[2]DADOS DA IATF'!G$7:G$16406,"X")+COUNTIFS('[2]DADOS DA IATF'!E$7:E$16406,C10,'[2]DADOS DA IATF'!K$7:K$16406,"SINCRONIZADA",'[2]DADOS DA IATF'!G$7:G$16406,"X") -> #VALUE! | I10: =COUNTIFS('[2]DADOS DA IATF'!E$7:E$16406,C10,'[2]DADOS DA IATF'!K$7:K$16406,"NÃO DG",'[2]DADOS DA IATF'!G$7:G$16406,"X") -> #VALUE!
C11: TOTAL | E11: =SUM(E6:F10) -> 0 | G11: =SUM(G6:H10) -> #VALUE! | I11: =SUM(I6:J10) -> #DIV/0! | K11: =SUM(K6:K11) -> #DIV/0!

Sheet Lotes
B2: Lotes
C5: Lote 1 | H5: Lote 6
C7: Lote 2 | H7: Lote 7
C9: Lote 3 | H9: Lote 8
C11: Lote 4 | H11: Lote 9
C13: Lote 5 | H13: Lote 10

Sheet Lote 01
A1: Lote | B1: Data IA | C1: Vaca | D1: E.C.C DG | E1: Diagnóstico | F1: E.C.C. IA | G1: Raça IA | H1: CIO | I1: Categoria | J1: Touro | K1: Partida | L1: Inseminador | M1: Observação | N1: Previsão de Parto | P1: Data IA | Q1: Coluna1 | R1: E.C.C DG | S1: Diagnóstico | T1: E.C.C. IA | U1: Raça IA | V1: CIO | W1: Categoria | X1: Touro | Y1: Partida | Z1: Inseminador | AA1: Observação | AB1: Previsão de Parto | AD1: Data IA | AE1: Vaca | AF1: E.C.C DG | AG1: Diagnóstico | AH1: E.C.C. IA | AI1: Raça IA | AJ1: CIO | AK1: Categoria | AL1: Touro | AM1: Partida | AN1: Inseminador | AO1: Observação | AP1: Previsão de Parto
A2: Vacas Par. Mês 09 | B2: 45977 | C2: 327 | E2: Não Prenha | F2: 2.25 | G2: SM | J2: Guapo | K2: 40232 | L2: Raimundo | N2: =IF(B2="","",SUM(B2+295)) -> 46272 | P2: 46032 | Q2: =IF(Tabela13[[#This Row],[Diagnóstico]]="Não Prenha",Tabela13[[#This Row],[Vaca]],"-") -> 327 | R2: =IF(Tabela13[[#This Row],[Diagnóstico]]="Não Prenha",Tabela13[[#This Row],[E.C.C DG]],"-") -> 0 | T2: =IF(Tabela13[[#This Row],[Diagnóstico]]="Não Prenha",Tabela13[[#This Row],[E.C.C. IA]],"-") -> 2.25 | U2: =IF(Tabela13[[#This Row],[Diagnóstico]]="Não Prenha",Tabela13[[#This Row],[Raça IA]],"-") -> SM | W2: =Tabela13[[#This Row],[Categoria]] -> 0 | X2: GUAPO | Y2: 40232 | Z2: RAIMUNDO | AB2: =IF(P2="","",SUM(P2+295)) -> 46327 | AE2: =IF(Tabela1312[[#This Row],[Diagnóstico]]="Não Prenha ",Tabela13[[#This Row],[Vaca]],"-") -> - | AK2: =Tabela13[[#This Row],[Categoria]] -> 0 | AP2: =IF(AD2="","",SUM(AD2+295))
A3: Vacas Par. Mês 09 | B3: 45977 | C3: 637 | E3: Não Prenha | F3: 2.75 | J3: Vagalume | K3: 45245 | L3: Raimundo | N3: =IF(B3="","",SUM(B3+295)) -> 46272 | P3: 46032 | Q3: =IF(Tabela13[[#This Row],[Diagnóstico]]="Não Prenha",Tabela13[[#This Row],[Vaca]],"-") -> 637 | R3: =IF(Tabela13[[#This Row],[Diagnóstico]]="Não Prenha",Tabela13[[#This Row],[E.C.C DG]],"-") -> 0 | T3: =IF(Tabela13[[#This Row],[Diagnóstico]]="Não Prenha",Tabela13[[#This Row],[E.C.C. IA]],"-") -> 2.75 | U3: =IF(Tabela13[[#This Row],[Diagnóstico]]="Não Prenha",Tabela13[[#This Row],[Raça IA]],"-") -> 0 | W3: =Tabela13[[#This Row],[Categoria]] -> 0 | X3: VAGALUME | Y3: 45210 | Z3: RAIMUNDO | AB3: =IF(P3="","",SUM(P3+295)) -> 46327 | AE3: =IF(Tabela1312[[#This Row],[Diagnóstico]]="Não Prenha ",Tabela13[[#This Row],[Vaca]],"-") -> - | AK3: =Tabela13[[#This Row],[Categoria]] -> 0 | AP3: =IF(AD3="","",SUM(AD3+295))
A4: Vacas Par. Mês 09 | B4: 45977 | C4: 1101 | E4: Não Prenha | F4: 2.25 | J4: Vagalume | K4: 45245 | L4: Raimundo | N4: =IF(B4="","",SUM(B4+295)) -> 46272 | P4: 46032 | Q4: =IF(Tabela13[[#This Row],[Diagnóstico]]="Não Prenha",Tabela13[[#This Row],[Vaca]],"-") -> 1101 | R4: =IF(Tabela13[[#This Row],[Diagnóstico]]="Não Prenha",Tabela13[[#This Row],[E.C.C DG]],"-") -> 0 | T4: =IF(Tabela13[[#This Row],[Diagnóstico]]="Não Prenha",Tabela13[[#This Row],[E.C.C. IA]],"-") -> 2.25 | U4: =IF(Tabela13[[#This Row],[Diagnóstico]]="Não Prenha",Tabela13[[#This Row],[Raça IA]],"-") -> 0 | W4: =Tabela13[[#This Row],[Categoria]] -> 0 | X4: VAGALUME | Y4: 45210 | Z4: RAIMUNDO | AB4: =IF(P4="","",SUM(P4+295)) -> 46327 | AE4: =IF(Tabela1312[[#This Row],[Diagnóstico]]="Não Prenha ",Tabela13[[#This Row],[Vaca]],"-") -> - | AK4: =Tabela13[[#This Row],[Categoria]] -> 0 | AP4: =IF(AD4="","",SUM(AD4+295))
A5: Vacas Par. Mês 09 | B5: 45977 | C5: 1120 | E5: Não Prenha | F5: 2.5 | J5: Vagalume | K5: 45245 | L5: Raimundo | N5: =IF(B5="","",SUM(B5+295)) -> 46272 | P5: 46032 | Q5: =IF(Tabela13[[#This Row],[Diagnóstico]]="Não Prenha",Tabela13[[#This Row],[Vaca]],"-") -> 1120 | R5: =IF(Tabela13[[#This Row],[Diagnóstico]]="Não Prenha",Tabela13[[#This Row],[E.C.C DG]],"-") -> 0 | T5: =IF(Tabela13[[#This Row],[Diagnóstico]]="Não Prenha",Tabela13[[#This Row],[E.C.C. IA]],"-") -> 2.5 | U5: =IF(Tabela13[[#This Row],[Diagnóstico]]="Não Prenha",Tabela13[[#This Row],[Raça IA]],"-") -> 0 | W5: =Tabela13[[#This Row],[Categoria]] -> 0 | X5: VAGALUME | Y5: 45210 | Z5: RAIMUNDO | AB5: =IF(P5="","",SUM(P5+295)) -> 46327 | AE5: =IF(Tabela1312[[#This Row],[Diagnóstico]]="Não Prenha ",Tabela13[[#This Row],[Vaca]],"-") -> - | AK5: =Tabela13[[#This Row],[Categoria]] -> 0 | AP5: =IF(AD5="","",SUM(AD5+295))
A6: Vacas Par. Mês 09 | B6: 45977 | C6: 1204 | E6: Prenha | F6: 2.25 | J6: Vagalume | K6: 45245 | L6: Raimundo | N6: =IF(B6="","",SUM(B6+295)) -> 46272 | Q6: =IF(Tabela13[[#This Row],[Diagnóstico]]="Não Prenha",Tabela13[[#This Row],[Vaca]],"-") -> - | R6: =IF(Tabela13[[#This Row],[Diagnóstico]]="Não Prenha",Tabela13[[#This Row],[E.C.C DG]],"-") -> - | T6: =IF(Tabela13[[#This Row],[Diagnóstico]]="Não Prenha",Tabela13[[#This Row],[E.C.C. IA]],"-") -> - | U6: =IF(Tabela13[[#This Row],[Diagnóstico]]="Não Prenha",Tabela13[[#This Row],[Raça IA]],"-") -> - | W6: =Tabela13[[#This Row],[Categoria]] -> 0 | AB6: =IF(P6="","",SUM(P6+295)) | AE6: =IF(Tabela1312[[#This Row],[Diagnóstico]]="Não Prenha ",Tabela13[[#This Row],[Vaca]],"-") -> - | AK6: =Tabela13[[#This Row],[Categoria]] -> 0 | AP6: =IF(AD6="","",SUM(AD6+295))
A7: Vacas Par. Mês 09 | B7: 45977 | C7: 1214 | E7: Prenha | F7: 3 | J7: Vagalume | K7: 45245 | L7: Raimundo | N7: =IF(B7="","",SUM(B7+295)) -> 46272 | Q7: =IF(Tabela13[[#This Row],[Diagnóstico]]="Não Prenha",Tabela13[[#This Row],[Vaca]],"-") -> - | R7: =IF(Tabela13[[#This Row],[Diagnóstico]]="Não Prenha",Tabela13[[#This Row],[E.C.C DG]],"-") -> - | T7: =IF(Tabela13[[#This Row],[Diagnóstico]]="Não Prenha",Tabela13[[#This Row],[E.C.C. IA]],"-") -> - | U7: =IF(Tabela13[[#This Row],[Diagnóstico]]="Não Prenha",Tabela13[[#This Row],[Raça IA]],"-") -> - | W7: =Tabela13[[#This Row],[Categoria]] -> 0 | AB7: =IF(P7="","",SUM(P7+295)) | AE7: =IF(Tabela1312[[#This Row],[Diagnóstico]]="Não Prenha ",Tabela13[[#This Row],[Vaca]],"-") -> - | AK7: =Tabela13[[#This Row],[Categoria]] -> 0 | AP7: =IF(AD7="","",SUM(AD7+295))
A8: Vacas Par. Mês 09 | B8: 45977 | C8: 1373 | E8: Não Prenha | F8: 2.5 | J8: Vagalume | K8: 45245 | L8: Raimundo | N8: =IF(B8="","",SUM(B8+295)) -> 46272 | P8: 46032 | Q8: =IF(Tabela13[[#This Row],[Diagnóstico]]="Não Prenha",Tabela13[[#This Row],[Vaca]],"-") -> 1373 | R8: =IF(Tabela13[[#This Row],[Diagnóstico]]="Não Prenha",Tabela13[[#This Row],[E.C.C DG]],"-") -> 0 | T8: =IF(Tabela13[[#This Row],[Diagnóstico]]="Não Prenha",Tabela13[[#This Row],[E.C.C. IA]],"-") -> 2.5 | U8: =IF(Tabela13[[#This Row],[Diagnóstico]]="Não Prenha",Tabela13[[#This Row],[Raça IA]],"-") -> 0 | W8: =Tabela13[[#This Row],[Categoria]] -> 0 | X8: VAGALUME | Y8: 45210 | Z8: RAIMUNDO | AB8: =IF(P8="","",SUM(P8+295)) -> 46327 | AE8: =IF(Tabela1312[[#This Row],[Diagnóstico]]="Não Prenha ",Tabela13[[#This Row],[Vaca]],"-") -> - | AK8: =Tabela13[[#This Row],[Categoria]] -> 0 | AP8: =IF(AD8="","",SUM(AD8+295))
A9: Vacas Par. Mês 09 | B9: 45977 | C9: 1470 | E9: Não Prenha | F9: 2.5 | J9: Vagalume | K9: 45245 | L9: Raimundo | N9: =IF(B9="","",SUM(B9+295)) -> 46272 | P9: 46032 | Q9: =IF(Tabela13[[#This Row],[Diagnóstico]]="Não Prenha",Tabela13[[#This Row],[Vaca]],"-") -> 1470 | R9: =IF(Tabela13[[#This Row],[Diagnóstico]]="Não Prenha",Tabela13[[#This Row],[E.C.C DG]],"-") -> 0 | T9: =IF(Tabela13[[#This Row],[Diagnóstico]]="Não Prenha",Tabela13[[#This Row],[E.C.C. IA]],"-") -> 2.5 | U9: =IF(Tabela13[[#This Row],[Diagnóstico]]="Não Prenha",Tabela13[[#This Row],[Raça IA]],"-") -> 0 | W9: =Tabela13[[#This Row],[Categoria]] -> 0 | X9: VAGALUME | Y9: 45210 | Z9: RAIMUNDO | AB9: =IF(P9="","",SUM(P9+295)) -> 46327 | AE9: =IF(Tabela1312[[#This Row],[Diagnóstico]]="Não Prenha ",Tabela13[[#This Row],[Vaca]],"-") -> - | AK9: =Tabela13[[#This Row],[Categoria]] -> 0 | AP9: =IF(AD9="","",SUM(AD9+295))
A10: Vacas Par. Mês 09 | B10: 45977 | C10: 1855 | E10: Prenha | F10: 3 | J10: Vagalume | K10: 45245 | L10: Raimundo | N10: =IF(B10="","",SUM(B10+295)) -> 46272 | Q10: =IF(Tabela13[[#This Row],[Diagnóstico]]="Não Prenha",Tabela13[[#This Row],[Vaca]],"-") -> - | R10: =IF(Tabela13[[#This Row],[Diagnóstico]]="Não Prenha",Tabela13[[#This Row],[E.C.C DG]],"-") -> - | T10: =IF(Tabela13[[#This Row],[Diagnóstico]]="Não Prenha",Tabela13[[#This Row],[E.C.C. IA]],"-") -> - | U10: =IF(Tabela13[[#This Row],[Diagnóstico]]="Não Prenha",Tabela13[[#This Row],[Raça IA]],"-") -> - | W10: =Tabela13[[#This Row],[Categoria]] -> 0 | AB10: =IF(P10="","",SUM(P10+295)) | AE10: =IF(Tabela1312[[#This Row],[Diagnóstico]]="Não Prenha ",Tabela13[[#This Row],[Vaca]],"-") -> - | AK10: =Tabela13[[#This Row],[Categoria]] -> 0 | AP10: =IF(AD10="","",SUM(AD10+295))
A11: Vacas Par. Mês 09 | B11: 45977 | C11: 1886 | E11: Não Prenha | F11: 2.75 | J11: Vagalume | K11: 45245 | L11: Raimundo | N11: =IF(B11="","",SUM(B11+295)) -> 46272 | P11: 46032 | Q11: =IF(Tabela13[[#This Row],[Diagnóstico]]="Não Prenha",Tabela13[[#This Row],[Vaca]],"-") -> 1886 | R11: =IF(Tabela13[[#This Row],[Diagnóstico]]="Não Prenha",Tabela13[[#This Row],[E.C.C DG]],"-") -> 0 | T11: =IF(Tabela13[[#This Row],[Diagnóstico]]="Não Prenha",Tabela13[[#This Row],[E.C.C. IA]],"-") -> 2.75 | U11: =IF(Tabela13[[#This Row],[Diagnóstico]]="Não Prenha",Tabela13[[#This Row],[Raça IA]],"-") -> 0 | W11: =Tabela13[[#This Row],[Categoria]] -> 0 | X11: VAGALUME | Y11: 45210 | Z11: RAIMUNDO | AB11: =IF(P11="","",SUM(P11+295)) -> 46327 | AE11: =IF(Tabela1312[[#This Row],[Diagnóstico]]="Não Prenha ",Tabela13[[#This Row],[Vaca]],"-") -> - | AK11: =Tabela13[[#This Row],[Categoria]] -> 0 | AP11: =IF(AD11="","",SUM(AD11+295))
A12: Vacas Par. Mês 09 | B12: 45977 | C12: 1911 | E12: Não Prenha | F12: 2.25 | J12: Vagalume | K12: 45245 | L12: Raimundo | N12: =IF(B12="","",SUM(B12+295)) -> 46272 | P12: 46032 | Q12: =IF(Tabela13[[#This Row],[Diagnóstico]]="Não Prenha",Tabela13[[#This Row],[Vaca]],"-") -> 1911 | R12: =IF(Tabela13[[#This Row],[Diagnóstico]]="Não Prenha",Tabela13[[#This Row],[E.C.C DG]],"-") -> 0 | T12: =IF(Tabela13[[#This Row],[Diagnóstico]]="Não Prenha",Tabela13[[#This Row],[E.C.C. IA]],"-") -> 2.25 | U12: =IF(Tabela13[[#This Row],[Diagnóstico]]="Não Prenha",Tabela13[[#This Row],[Raça IA]],"-") -> 0 | W12: =Tabela13[[#This Row],[Categoria]] -> 0 | X12: VAGALUME | Y12: 45210 | Z12: RAIMUNDO | AB12: =IF(P12="","",SUM(P12+295)) -> 46327 | AE12: =IF(Tabela1312[[#This Row],[Diagnóstico]]="Não Prenha ",Tabela13[[#This Row],[Vaca]],"-") -> - | AK12: =Tabela13[[#This Row],[Categoria]] -> 0 | AP12: =IF(AD12="","",SUM(AD12+295))
A13: Vacas Par. Mês 09 | B13: 45977 | C13: 1947 | E13: Não Prenha | F13: 2.75 | J13: Vagalume | K13: 45245 | L13: Raimundo | N13: =IF(B13="","",SUM(B13+295)) -> 46272 | P13: 46032 | Q13: =IF(Tabela13[[#This Row],[Diagnóstico]]="Não Prenha",Tabela13[[#This Row],[Vaca]],"-") -> 1947 | R13: =IF(Tabela13[[#This Row],[Diagnóstico]]="Não Prenha",Tabela13[[#This Row],[E.C.C DG]],"-") -> 0 | T13: =IF(Tabela13[[#This Row],[Diagnóstico]]="Não Prenha",Tabela13[[#This Row],[E.C.C. IA]],"-") -> 2.75 | U13: =IF(Tabela13[[#This Row],[Diagnóstico]]="Não Prenha",Tabela13[[#This Row],[Raça IA]],"-") -> 0 | W13: =Tabela13[[#This Row],[Categoria]] -> 0 | X13: VAGALUME | Y13: 45210 | Z13: RAIMUNDO | AB13: =IF(P13="","",SUM(P13+295)) -> 46327 | AE13: =IF(Tabela1312[[#This Row],[Diagnóstico]]="Não Prenha ",Tabela13[[#This Row],[Vaca]],"-") -> - | AK13: =Tabela13[[#This Row],[Categoria]] -> 0 | AP13: =IF(AD13="","",SUM(AD13+295))
A14: Vacas Par. Mês 09 | B14: 45977 | C14: 1978 | E14: Não Prenha | F14: 2.5 | G14: SM | J14: Guapo | K14: 40232 | L14: Raimundo | N14: =IF(B14="","",SUM(B14+295)) -> 46272 | P14: 46032 | Q14: =IF(Tabela13[[#This Row],[Diagnóstico]]="Não Prenha",Tabela13[[#This Row],[Vaca]],"-") -> 1978 | R14: =IF(Tabela13[[#This Row],[Diagnóstico]]="Não Prenha",Tabela13[[#This Row],[E.C.C DG]],"-") -> 0 | T14: =IF(Tabela13[[#This Row],[Diagnóstico]]="Não Prenha",Tabela13[[#This Row],[E.C.C. IA]],"-") -> 2.5 | U14: =IF(Tabela13[[#This Row],[Diagnóstico]]="Não Prenha",Tabela13[[#This Row],[Raça IA]],"-") -> SM | W14: =Tabela13[[#This Row],[Categoria]] -> 0 | X14: GUAPO | Y14: 40232 | Z14: RAIMUNDO | AB14: =IF(P14="","",SUM(P14+295)) -> 46327 | AE14: =IF(Tabela1312[[#This Row],[Diagnóstico]]="Não Prenha ",Tabela13[[#This Row],[Vaca]],"-") -> - | AK14: =Tabela13[[#This Row],[Categoria]] -> 0 | AP14: =IF(AD14="","",SUM(AD14+295))
A15: Vacas Par. Mês 09 | B15: 45977 | C15: 2069 | E15: Não Prenha | F15: 2.75 | J15: Vagalume | K15: 45245 | L15: Raimundo | N15: =IF(B15="","",SUM(B15+295)) -> 46272 | P15: 46032 | Q15: =IF(Tabela13[[#This Row],[Diagnóstico]]="Não Prenha",Tabela13[[#This Row],[Vaca]],"-") -> 2069 | R15: =IF(Tabela13[[#This Row],[Diagnóstico]]="Não Prenha",Tabela13[[#This Row],[E.C.C DG]],"-") -> 0 | T15: =IF(Tabela13[[#This Row],[Diagnóstico]]="Não Prenha",Tabela13[[#This Row],[E.C.C. IA]],"-") -> 2.75 | U15: =IF(Tabela13[[#This Row],[Diagnóstico]]="Não Prenha",Tabela13[[#This Row],[Raça IA]],"-") -> 0 | W15: =Tabela13[[#This Row],[Categoria]] -> 0 | X15: VAGALUME | Y15: 45210 | Z15: RAIMUNDO | AB15: =IF(P15="","",SUM(P15+295)) -> 46327 | AE15: =IF(Tabela1312[[#This Row],[Diagnóstico]]="Não Prenha ",Tabela13[[#This Row],[Vaca]],"-") -> - | AK15: =Tabela13[[#This Row],[Categoria]] -> 0 | AP15: =IF(AD15="","",SUM(AD15+295))
A16: Vacas Par. Mês 09 | B16: 45977 | C16: 2139 | E16: Não Prenha | F16: 2.75 | G16: SM | J16: Guapo | K16: 40232 | L16: Raimundo | N16: =IF(B16="","",SUM(B16+295)) -> 46272 | P16: 46032 | Q16: =IF(Tabela13[[#This Row],[Diagnóstico]]="Não Prenha",Tabela13[[#This Row],[Vaca]],"-") -> 2139 | R16: =IF(Tabela13[[#This Row],[Diagnóstico]]="Não Prenha",Tabela13[[#This Row],[E.C.C DG]],"-") -> 0 | T16: =IF(Tabela13[[#This Row],[Diagnóstico]]="Não Prenha",Tabela13[[#This Row],[E.C.C. IA]],"-") -> 2.75 | U16: =IF(Tabela13[[#This Row],[Diagnóstico]]="Não Prenha",Tabela13[[#This Row],[Raça IA]],"-") -> SM | W16: =Tabela13[[#This Row],[Categoria]] -> 0 | X16: GUAPO | Y16: 40232 | Z16: RAIMUNDO | AB16: =IF(P16="","",SUM(P16+295)) -> 46327 | AE16: =IF(Tabela1312[[#This Row],[Diagnóstico]]="Não Prenha ",Tabela13[[#This Row],[Vaca]],"-") -> - | AK16: =Tabela13[[#This Row],[Categoria]] -> 0 | AP16: =IF(AD16="","",SUM(AD16+295))
A17: Vacas Par. Mês 09 | B17: 45977 | C17: 2177 | E17: Não Prenha | F17: 2.25 | J17: Vagalume | K17: 45245 | L17: Raimundo | N17: =IF(B17="","",SUM(B17+295)) -> 46272 | P17: 46032 | Q17: =IF(Tabela13[[#This Row],[Diagnóstico]]="Não Prenha",Tabela13[[#This Row],[Vaca]],"-") -> 2177 | R17: =IF(Tabela13[[#This Row],[Diagnóstico]]="Não Prenha",Tabela13[[#This Row],[E.C.C DG]],"-") -> 0 | T17: =IF(Tabela13[[#This Row],[Diagnóstico]]="Não Prenha",Tabela13[[#This Row],[E.C.C. IA]],"-") -> 2.25 | U17: =IF(Tabela13[[#This Row],[Diagnóstico]]="Não Prenha",Tabela13[[#This Row],[Raça IA]],"-") -> 0 | W17: =Tabela13[[#This Row],[Categoria]] -> 0 | X17: VAGALUME | Y17: 45210 | Z17: RAIMUNDO | AB17: =IF(P17="","",SUM(P17+295)) -> 46327 | AE17: =IF(Tabela1312[[#This Row],[Diagnóstico]]="Não Prenha ",Tabela13[[#This Row],[Vaca]],"-") -> - | AK17: =Tabela13[[#This Row],[Categoria]] -> 0 | AP17: =IF(AD17="","",SUM(AD17+295))
A18: Vacas Par. Mês 09 | B18: 45977 | C18: 2244 | E18: Prenha | F18: 2.75 | J18: Vagalume | K18: 45245 | L18: Raimundo | N18: =IF(B18="","",SUM(B18+295)) -> 46272 | Q18: =IF(Tabela13[[#This Row],[Diagnóstico]]="Não Prenha",Tabela13[[#This Row],[Vaca]],"-") -> - | R18: =IF(Tabela13[[#This Row],[Diagnóstico]]="Não Prenha",Tabela13[[#This Row],[E.C.C DG]],"-") -> - | T18: =IF(Tabela13[[#This Row],[Diagnóstico]]="Não Prenha",Tabela13[[#This Row],[E.C.C. IA]],"-") -> - | U18: =IF(Tabela13[[#This Row],[Diagnóstico]]="Não Prenha",Tabela13[[#This Row],[Raça IA]],"-") -> - | W18: =Tabela13[[#This Row],[Categoria]] -> 0 | AB18: =IF(P18="","",SUM(P18+295)) | AE18: =IF(Tabela1312[[#This Row],[Diagnóstico]]="Não Prenha ",Tabela13[[#This Row],[Vaca]],"-") -> - | AK18: =Tabela13[[#This Row],[Categoria]] -> 0 | AP18: =IF(AD18="","",SUM(AD18+295))
A19: Vacas Par. Mês 09 | B19: 45977 | C19: 2246 | E19: Não Prenha | F19: 2.25 | J19: Vagalume | K19: 45245 | L19: Raimundo | N19: =IF(B19="","",SUM(B19+295)) -> 46272 | P19: 46032 | Q19: =IF(Tabela13[[#This Row],[Diagnóstico]]="Não Prenha",Tabela13[[#This Row],[Vaca]],"-") -> 2246 | R19: =IF(Tabela13[[#This Row],[Diagnóstico]]="Não Prenha",Tabela13[[#This Row],[E.C.C DG]],"-") -> 0 | T19: =IF(Tabela13[[#This Row],[Diagnóstico]]="Não Prenha",Tabela13[[#This Row],[E.C.C. IA]],"-") -> 2.25 | U19: =IF(Tabela13[[#This Row],[Diagnóstico]]="Não Prenha",Tabela13[[#This Row],[Raça IA]],"-") -> 0 | W19: =Tabela13[[#This Row],[Categoria]] -> 0 | X19: VAGALUME | Y19: 45210 | Z19: RAIMUNDO | AB19: =IF(P19="","",SUM(P19+295)) -> 46327 | AE19: =IF(Tabela1312[[#This Row],[Diagnóstico]]="Não Prenha ",Tabela13[[#This Row],[Vaca]],"-") -> - | AK19: =Tabela13[[#This Row],[Categoria]] -> 0 | AP19: =IF(AD19="","",SUM(AD19+295))
A20: Vacas Par. Mês 09 | B20: 45977 | C20: 2255 | E20: Prenha | F20: 2.75 | G20: SM | J20: Guapo | K20: 40232 | L20: Raimundo | N20: =IF(B20="","",SUM(B20+295)) -> 46272 | Q20: =IF(Tabela13[[#This Row],[Diagnóstico]]="Não Prenha",Tabela13[[#This Row],[Vaca]],"-") -> - | R20: =IF(Tabela13[[#This Row],[Diagnóstico]]="Não Prenha",Tabela13[[#This Row],[E.C.C DG]],"-") -> - | T20: =IF(Tabela13[[#This Row],[Diagnóstico]]="Não Prenha",Tabela13[[#This Row],[E.C.C. IA]],"-") -> - | U20: =IF(Tabela13[[#This Row],[Diagnóstico]]="Não Prenha",Tabela13[[#This Row],[Raça IA]],"-") -> - | W20: =Tabela13[[#This Row],[Categoria]] -> 0 | AB20: =IF(P20="","",SUM(P20+295)) | AE20: =IF(Tabela1312[[#This Row],[Diagnóstico]]="Não Prenha ",Tabela13[[#This Row],[Vaca]],"-") -> - | AK20: =Tabela13[[#This Row],[Categoria]] -> 0 | AP20: =IF(AD20="","",SUM(AD20+295))
A21: Vacas Par. Mês 09 | B21: 45977 | C21: 2557 | E21: Prenha | F21: 2.75 | G21: SM | J21: Guapo | K21: 40232 | L21: Raimundo | N21: =IF(B21="","",SUM(B21+295)) -> 46272 | Q21: =IF(Tabela13[[#This Row],[Diagnóstico]]="Não Prenha",Tabela13[[#This Row],[Vaca]],"-") -> - | R21: =IF(Tabela13[[#This Row],[Diagnóstico]]="Não Prenha",Tabela13[[#This Row],[E.C.C DG]],"-") -> - | T21: =IF(Tabela13[[#This Row],[Diagnóstico]]="Não Prenha",Tabela13[[#This Row],[E.C.C. IA]],"-") -> - | U21: =IF(Tabela13[[#This Row],[Diagnóstico]]="Não Prenha",Tabela13[[#This Row],[Raça IA]],"-") -> - | W21: =Tabela13[[#This Row],[Categoria]] -> 0 | AB21: =IF(P21="","",SUM(P21+295)) | AE21: =IF(Tabela1312[[#This Row],[Diagnóstico]]="Não Prenha ",Tabela13[[#This Row],[Vaca]],"-") -> - | AK21: =Tabela13[[#This Row],[Categoria]] -> 0 | AP21: =IF(AD21="","",SUM(AD21+295))
A22: Vacas Par. Mês 09 | B22: 45977 | C22: 2564 | E22: Não Prenha | F22: 2.75 | G22: SM | J22: Guapo | K22: 40232 | L22: Raimundo | N22: =IF(B22="","",SUM(B22+295)) -> 46272 | P22: 46032 | Q22: =IF(Tabela13[[#This Row],[Diagnóstico]]="Não Prenha",Tabela13[[#This Row],[Vaca]],"-") -> 2564 | R22: =IF(Tabela13[[#This Row],[Diagnóstico]]="Não Prenha",Tabela13[[#This Row],[E.C.C DG]],"-") -> 0 | T22: =IF(Tabela13[[#This Row],[Diagnóstico]]="Não Prenha",Tabela13[[#This Row],[E.C.C. IA]],"-") -> 2.75 | U22: =IF(Tabela13[[#This Row],[Diagnóstico]]="Não Prenha",Tabela13[[#This Row],[Raça IA]],"-") -> SM | W22: =Tabela13[[#This Row],[Categoria]] -> 0 | X22: GUAPO | Y22: 40232 | Z22: RAIMUNDO | AB22: =IF(P22="","",SUM(P22+295)) -> 46327 | AE22: =IF(Tabela1312[[#This Row],[Diagnóstico]]="Não Prenha ",Tabela13[[#This Row],[Vaca]],"-") -> - | AK22: =Tabela13[[#This Row],[Categoria]] -> 0 | AP22: =IF(AD22="","",SUM(AD22+295))
A23: Vacas Par. Mês 09 | B23: 45977 | C23: 2606 | E23: Não Prenha | F23: 2.25 | G23: SM | J23: Guapo | K23: 40232 | L23: Raimundo | N23: =IF(B23="","",SUM(B23+295)) -> 46272 | P23: 46032 | Q23: =IF(Tabela13[[#This Row],[Diagnóstico]]="Não Prenha",Tabela13[[#This Row],[Vaca]],"-") -> 2606 | R23: =IF(Tabela13[[#This Row],[Diagnóstico]]="Não Prenha",Tabela13[[#This Row],[E.C.C DG]],"-") -> 0 | T23: =IF(Tabela13[[#This Row],[Diagnóstico]]="Não Prenha",Tabela13[[#This Row],[E.C.C. IA]],"-") -> 2.25 | U23: =IF(Tabela13[[#This Row],[Diagnóstico]]="Não Prenha",Tabela13[[#This Row],[Raça IA]],"-") -> SM | W23: =Tabela13[[#This Row],[Categoria]] -> 0 | X23: GUAPO | Y23: 40232 | Z23: RAIMUNDO | AB23: =IF(P23="","",SUM(P23+295)) -> 46327 | AE23: =IF(Tabela1312[[#This Row],[Diagnóstico]]="Não Prenha ",Tabela13[[#This Row],[Vaca]],"-") -> - | AK23: =Tabela13[[#This Row],[Categoria]] -> 0 | AP23: =IF(AD23="","",SUM(AD23+295))
A24: Vacas Par. Mês 09 | B24: 45977 | C24: 2681 | N24: =IF(B24="","",SUM(B24+295)) -> 46272 | Q24: =IF(Tabela13[[#This Row],[Diagnóstico]]="Não Prenha",Tabela13[[#This Row],[Vaca]],"-") -> - | R24: =IF(Tabela13[[#This Row],[Diagnóstico]]="Não Prenha",Tabela13[[#This Row],[E.C.C DG]],"-") -> - | T24: =IF(Tabela13[[#This Row],[Diagnóstico]]="Não Prenha",Tabela13[[#This Row],[E.C.C. IA]],"-") -> - | U24: =IF(Tabela13[[#This Row],[Diagnóstico]]="Não Prenha",Tabela13[[#This Row],[Raça IA]],"-") -> - | W24: =Tabela13[[#This Row],[Categoria]] -> 0 | AB24: =IF(P24="","",SUM(P24+295)) | AE24: =IF(Tabela1312[[#This Row],[Diagnóstico]]="Não Prenha ",Tabela13[[#This Row],[Vaca]],"-") -> - | AK24: =Tabela13[[#This Row],[Categoria]] -> 0 | AP24: =IF(AD24="","",SUM(AD24+295))
A25: Vacas Par. Mês 09 | B25: 45977 | C25: 3100 | E25: Não Prenha | F25: 2.5 | G25: SM | J25: Guapo | K25: 40232 | L25: Raimundo | N25: =IF(B25="","",SUM(B25+295)) -> 46272 | P25: 46032 | Q25: =IF(Tabela13[[#This Row],[Diagnóstico]]="Não Prenha",Tabela13[[#This Row],[Vaca]],"-") -> 3100 | R25: =IF(Tabela13[[#This Row],[Diagnóstico]]="Não Prenha",Tabela13[[#This Row],[E.C.C DG]],"-") -> 0 | T25: =IF(Tabela13[[#This Row],[Diagnóstico]]="Não Prenha",Tabela13[[#This Row],[E.C.C. IA]],"-") -> 2.5 | U25: =IF(Tabela13[[#This Row],[Diagnóstico]]="Não Prenha",Tabela13[[#This Row],[Raça IA]],"-") -> SM | W25: =Tabela13[[#This Row],[Categoria]] -> 0 | X25: GUAPO | Y25: 40232 | AB25: =IF(P25="","",SUM(P25+295)) -> 46327 | AE25: =IF(Tabela1312[[#This Row],[Diagnóstico]]="Não Prenha ",Tabela13[[#This Row],[Vaca]],"-") -> - | AK25: =Tabela13[[#This Row],[Categoria]] -> 0 | AP25: =IF(AD25="","",SUM(AD25+295))
A26: Vacas Par. Mês 09 | B26: 45977 | C26: 3112 | E26: Não Prenha | F26: 3 | G26: SM | J26: Guapo | K26: 40232 | L26: Raimundo | N26: =IF(B26="","",SUM(B26+295)) -> 46272 | P26: 46032 | Q26: =IF(Tabela13[[#This Row],[Diagnóstico]]="Não Prenha",Tabela13[[#This Row],[Vaca]],"-") -> 3112 | R26: =IF(Tabela13[[#This Row],[Diagnóstico]]="Não Prenha",Tabela13[[#This Row],[E.C.C DG]],"-") -> 0 | T26: =IF(Tabela13[[#This Row],[Diagnóstico]]="Não Prenha",Tabela13[[#This Row],[E.C.C. IA]],"-") -> 3 | U26: =IF(Tabela13[[#This Row],[Diagnóstico]]="Não Prenha",Tabela13[[#This Row],[Raça IA]],"-") -> SM | W26: =Tabela13[[#This Row],[Categoria]] -> 0 | X26: GUAPO | Y26: 40232 | AB26: =IF(P26="","",SUM(P26+295)) -> 46327 | AE26: =IF(Tabela1312[[#This Row],[Diagnóstico]]="Não Prenha ",Tabela13[[#This Row],[Vaca]],"-") -> - | AK26: =Tabela13[[#This Row],[Categoria]] -> 0 | AP26: =IF(AD26="","",SUM(AD26+295))
A27: Vacas Par. Mês 09 | B27: 45977 | C27: 4151 | E27: Não Prenha | F27: 2.5 | G27: SM | J27: Guapo | K27: 40232 | L27: Raimundo | N27: =IF(B27="","",SUM(B27+295)) -> 46272 | P27: 46032 | Q27: =IF(Tabela13[[#This Row],[Diagnóstico]]="Não Prenha",Tabela13[[#This Row],[Vaca]],"-") -> 4151 | R27: =IF(Tabela13[[#This Row],[Diagnóstico]]="Não Prenha",Tabela13[[#This Row],[E.C.C DG]],"-") -> 0 | T27: =IF(Tabela13[[#This Row],[Diagnóstico]]="Não Prenha",Tabela13[[#This Row],[E.C.C. IA]],"-") -> 2.5 | U27: =IF(Tabela13[[#This Row],[Diagnóstico]]="Não Prenha",Tabela13[[#This Row],[Raça IA]],"-") -> SM | W27: =Tabela13[[#This Row],[Categoria]] -> 0 | X27: GUAPO | Y27: 40232 | AB27: =IF(P27="","",SUM(P27+295)) -> 46327 | AE27: =IF(Tabela1312[[#This Row],[Diagnóstico]]="Não Prenha ",Tabela13[[#This Row],[Vaca]],"-") -> - | AK27: =Tabela13[[#This Row],[Categoria]] -> 0 | AP27: =IF(AD27="","",SUM(AD27+295))
A28: Vacas Par. Mês 09 | B28: 45977 | C28: 4157 | N28: =IF(B28="","",SUM(B28+295)) -> 46272 | Q28: =IF(Tabela13[[#This Row],[Diagnóstico]]="Não Prenha",Tabela13[[#This Row],[Vaca]],"-") -> - | R28: =IF(Tabela13[[#This Row],[Diagnóstico]]="Não Prenha",Tabela13[[#This Row],[E.C.C DG]],"-") -> - | T28: =IF(Tabela13[[#This Row],[Diagnóstico]]="Não Prenha",Tabela13[[#This Row],[E.C.C. IA]],"-") -> - | U28: =IF(Tabela13[[#This Row],[Diagnóstico]]="Não Prenha",Tabela13[[#This Row],[Raça IA]],"-") -> - | W28: =Tabela13[[#This Row],[Categoria]] -> 0 | AB28: =IF(P28="","",SUM(P28+295)) | AE28: =IF(Tabela1312[[#This Row],[Diagnóstico]]="Não Prenha ",Tabela13[[#This Row],[Vaca]],"-") -> - | AK28: =Tabela13[[#This Row],[Categoria]] -> 0 | AP28: =IF(AD28="","",SUM(AD28+295))
A29: Vacas Par. Mês 09 | B29: 45977 | C29: S/N | E29: Não Prenha | F29: 2.75 | J29: Vagalume | K29: 45245 | L29: Raimundo | N29: =IF(B29="","",SUM(B29+295)) -> 46272 | P29: 46032 | Q29: =IF(Tabela13[[#This Row],[Diagnóstico]]="Não Prenha",Tabela13[[#This Row],[Vaca]],"-") -> S/N | R29: =IF(Tabela13[[#This Row],[Diagnóstico]]="Não Prenha",Tabela13[[#This Row],[E.C.C DG]],"-") -> 0 | T29: =IF(Tabela13[[#This Row],[Diagnóstico]]="Não Prenha",Tabela13[[#This Row],[E.C.C. IA]],"-") -> 2.75 | U29: =IF(Tabela13[[#This Row],[Diagnóstico]]="Não Prenha",Tabela13[[#This Row],[Raça IA]],"-") -> 0 | W29: =Tabela13[[#This Row],[Categoria]] -> 0 | X29: VAGALUME | Y29: 45210 | AB29: =IF(P29="","",SUM(P29+295)) -> 46327 | AE29: =IF(Tabela1312[[#This Row],[Diagnóstico]]="Não Prenha ",Tabela13[[#This Row],[Vaca]],"-") -> - | AK29: =Tabela13[[#This Row],[Categoria]] -> 0 | AP29: =IF(AD29="","",SUM(AD29+295))
A30: Vacas Par. Mês 09 | B30: 45977 | C30: S/N | N30: =IF(B30="","",SUM(B30+295)) -> 46272 | Q30: =IF(Tabela13[[#This Row],[Diagnóstico]]="Não Prenha",Tabela13[[#This Row],[Vaca]],"-") -> - | R30: =IF(Tabela13[[#This Row],[Diagnóstico]]="Não Prenha",Tabela13[[#This Row],[E.C.C DG]],"-") -> - | T30: =IF(Tabela13[[#This Row],[Diagnóstico]]="Não Prenha",Tabela13[[#This Row],[E.C.C. IA]],"-") -> - | U30: =IF(Tabela13[[#This Row],[Diagnóstico]]="Não Prenha",Tabela13[[#This Row],[Raça IA]],"-") -> - | W30: =Tabela13[[#This Row],[Categoria]] -> 0 | AB30: =IF(P30="","",SUM(P30+295)) | AE30: =IF(Tabela1312[[#This Row],[Diagnóstico]]="Não Prenha ",Tabela13[[#This Row],[Vaca]],"-") -> - | AK30: =Tabela13[[#This Row],[Categoria]] -> 0 | AP30: =IF(AD30="","",SUM(AD30+295))
C31: 159 | E31: Não Prenha | F31: 2.25 | J31: Vagalume | K31: 45245 | L31: Raimundo | N31: =IF(B31="","",SUM(B31+295)) | P31: 46032 | Q31: =IF(Tabela13[[#This Row],[Diagnóstico]]="Não Prenha",Tabela13[[#This Row],[Vaca]],"-") -> 159 | R31: =IF(Tabela13[[#This Row],[Diagnóstico]]="Não Prenha",Tabela13[[#This Row],[E.C.C DG]],"-") -> 0 | T31: =IF(Tabela13[[#This Row],[Diagnóstico]]="Não Prenha",Tabela13[[#This Row],[E.C.C. IA]],"-") -> 2.25 | U31: =IF(Tabela13[[#This Row],[Diagnóstico]]="Não Prenha",Tabela13[[#This Row],[Raça IA]],"-") -> 0 | W31: =Tabela13[[#This Row],[Categoria]] -> 0 | X31: VAGALUME | Y31: 45210 | AB31: =IF(P31="","",SUM(P31+295)) -> 46327 | AE31: =IF(Tabela1312[[#This Row],[Diagnóstico]]="Não Prenha ",Tabela13[[#This Row],[Vaca]],"-") -> - | AK31: =Tabela13[[#This Row],[Categoria]] -> 0 | AP31: =IF(AD31="","",SUM(AD31+295))
C32: 4150 | E32: Não Prenha | F32: 2 | G32: SM | J32: Guapo | K32: 40232 | L32: Raimundo | N32: =IF(B32="","",SUM(B32+295)) | P32: 46032 | Q32: =IF(Tabela13[[#This Row],[Diagnóstico]]="Não Prenha",Tabela13[[#This Row],[Vaca]],"-") -> 4150 | R32: =IF(Tabela13[[#This Row],[Diagnóstico]]="Não Prenha",Tabela13[[#This Row],[E.C.C DG]],"-") -> 0 | T32: =IF(Tabela13[[#This Row],[Diagnóstico]]="Não Prenha",Tabela13[[#This Row],[E.C.C. IA]],"-") -> 2 | U32: =IF(Tabela13[[#This Row],[Diagnóstico]]="Não Prenha",Tabela13[[#This Row],[Raça IA]],"-") -> SM | W32: =Tabela13[[#This Row],[Categoria]] -> 0 | X32: GUAPO | Y32: 40232 | AB32: =IF(P32="","",SUM(P32+295)) -> 46327 | AE32: =IF(Tabela1312[[#This Row],[Diagnóstico]]="Não Prenha ",Tabela13[[#This Row],[Vaca]],"-") -> - | AK32: =Tabela13[[#This Row],[Categoria]] -> 0 | AP32: =IF(AD32="","",SUM(AD32+295))
C33: 2591 | E33: Não Prenha | F33: 3 | G33: SM | J33: Guapo | K33: 40232 | L33: Raimundo | N33: =IF(B33="","",SUM(B33+295)) | P33: 46032 | Q33: =IF(Tabela13[[#This Row],[Diagnóstico]]="Não Prenha",Tabela13[[#This Row],[Vaca]],"-") -> 2591 | R33: =IF(Tabela13[[#This Row],[Diagnóstico]]="Não Prenha",Tabela13[[#This Row],[E.C.C DG]],"-") -> 0 | T33: =IF(Tabela13[[#This Row],[Diagnóstico]]="Não Prenha",Tabela13[[#This Row],[E.C.C. IA]],"-") -> 3 | U33: =IF(Tabela13[[#This Row],[Diagnóstico]]="Não Prenha",Tabela13[[#This Row],[Raça IA]],"-") -> SM | W33: =Tabela13[[#This Row],[Categoria]] -> 0 | X33: GUAPO | Y33: 40232 | AB33: =IF(P33="","",SUM(P33+295)) -> 46327 | AE33: =IF(Tabela1312[[#This Row],[Diagnóstico]]="Não Prenha ",Tabela13[[#This Row],[Vaca]],"-") -> - | AK33: =Tabela13[[#This Row],[Categoria]] -> 0 | AP33: =IF(AD33="","",SUM(AD33+295))
N34: =IF(B34="","",SUM(B34+295)) | Q34: =IF(Tabela13[[#This Row],[Diagnóstico]]="Não Prenha",Tabela13[[#This Row],[Vaca]],"-") -> - | R34: =IF(Tabela13[[#This Row],[Diagnóstico]]="Não Prenha",Tabela13[[#This Row],[E.C.C DG]],"-") -> - | T34: =IF(Tabela13[[#This Row],[Diagnóstico]]="Não Prenha",Tabela13[[#This Row],[E.C.C. IA]],"-") -> - | U34: =IF(Tabela13[[#This Row],[Diagnóstico]]="Não Prenha",Tabela13[[#This Row],[Raça IA]],"-") -> - | W34: =Tabela13[[#This Row],[Categoria]] -> 0 | AB34: =IF(P34="","",SUM(P34+295)) | AE34: =IF(Tabela1312[[#This Row],[Diagnóstico]]="Não Prenha ",Tabela13[[#This Row],[Vaca]],"-") -> - | AK34: =Tabela13[[#This Row],[Categoria]] -> 0 | AP34: =IF(AD34="","",SUM(AD34+295))
N35: =IF(B35="","",SUM(B35+295)) | Q35: =IF(Tabela13[[#This Row],[Diagnóstico]]="Não Prenha",Tabela13[[#This Row],[Vaca]],"-") -> - | R35: =IF(Tabela13[[#This Row],[Diagnóstico]]="Não Prenha",Tabela13[[#This Row],[E.C.C DG]],"-") -> - | T35: =IF(Tabela13[[#This Row],[Diagnóstico]]="Não Prenha",Tabela13[[#This Row],[E.C.C. IA]],"-") -> - | U35: =IF(Tabela13[[#This Row],[Diagnóstico]]="Não Prenha",Tabela13[[#This Row],[Raça IA]],"-") -> - | W35: =Tabela13[[#This Row],[Categoria]] -> 0 | AB35: =IF(P35="","",SUM(P35+295)) | AE35: =IF(Tabela1312[[#This Row],[Diagnóstico]]="Não Prenha ",Tabela13[[#This Row],[Vaca]],"-") -> - | AK35: =Tabela13[[#This Row],[Categoria]] -> 0 | AP35: =IF(AD35="","",SUM(AD35+295))
N36: =IF(B36="","",SUM(B36+295)) | Q36: =IF(Tabela13[[#This Row],[Diagnóstico]]="Não Prenha",Tabela13[[#This Row],[Vaca]],"-") -> - | R36: =IF(Tabela13[[#This Row],[Diagnóstico]]="Não Prenha",Tabela13[[#This Row],[E.C.C DG]],"-") -> - | T36: =IF(Tabela13[[#This Row],[Diagnóstico]]="Não Prenha",Tabela13[[#This Row],[E.C.C. IA]],"-") -> - | U36: =IF(Tabela13[[#This Row],[Diagnóstico]]="Não Prenha",Tabela13[[#This Row],[Raça IA]],"-") -> - | W36: =Tabela13[[#This Row],[Categoria]] -> 0 | AB36: =IF(P36="","",SUM(P36+295)) | AE36: =IF(Tabela1312[[#This Row],[Diagnóstico]]="Não Prenha ",Tabela13[[#This Row],[Vaca]],"-") -> - | AK36: =Tabela13[[#This Row],[Categoria]] -> 0 | AP36: =IF(AD36="","",SUM(AD36+295))
N37: =IF(B37="","",SUM(B37+295)) | Q37: =IF(Tabela13[[#This Row],[Diagnóstico]]="Não Prenha",Tabela13[[#This Row],[Vaca]],"-") -> - | R37: =IF(Tabela13[[#This Row],[Diagnóstico]]="Não Prenha",Tabela13[[#This Row],[E.C.C DG]],"-") -> - | T37: =IF(Tabela13[[#This Row],[Diagnóstico]]="Não Prenha",Tabela13[[#This Row],[E.C.C. IA]],"-") -> - | U37: =IF(Tabela13[[#This Row],[Diagnóstico]]="Não Prenha",Tabela13[[#This Row],[Raça IA]],"-") -> - | W37: =Tabela13[[#This Row],[Categoria]] -> 0 | AB37: =IF(P37="","",SUM(P37+295)) | AE37: =IF(Tabela1312[[#This Row],[Diagnóstico]]="Não Prenha ",Tabela13[[#This Row],[Vaca]],"-") -> - | AK37: =Tabela13[[#This Row],[Categoria]] -> 0 | AP37: =IF(AD37="","",SUM(AD37+295))
N38: =IF(B38="","",SUM(B38+295)) | Q38: =IF(Tabela13[[#This Row],[Diagnóstico]]="Não Prenha",Tabela13[[#This Row],[Vaca]],"-") -> - | R38: =IF(Tabela13[[#This Row],[Diagnóstico]]="Não Prenha",Tabela13[[#This Row],[E.C.C DG]],"-") -> - | T38: =IF(Tabela13[[#This Row],[Diagnóstico]]="Não Prenha",Tabela13[[#This Row],[E.C.C. IA]],"-") -> - | U38: =IF(Tabela13[[#This Row],[Diagnóstico]]="Não Prenha",Tabela13[[#This Row],[Raça IA]],"-") -> - | W38: =Tabela13[[#This Row],[Categoria]] -> 0 | AB38: =IF(P38="","",SUM(P38+295)) | AE38: =IF(Tabela1312[[#This Row],[Diagnóstico]]="Não Prenha ",Tabela13[[#This Row],[Vaca]],"-") -> - | AK38: =Tabela13[[#This Row],[Categoria]] -> 0 | AP38: =IF(AD38="","",SUM(AD38+295))
N39: =IF(B39="","",SUM(B39+295)) | Q39: =IF(Tabela13[[#This Row],[Diagnóstico]]="Não Prenha",Tabela13[[#This Row],[Vaca]],"-") -> - | R39: =IF(Tabela13[[#This Row],[Diagnóstico]]="Não Prenha",Tabela13[[#This Row],[E.C.C DG]],"-") -> - | T39: =IF(Tabela13[[#This Row],[Diagnóstico]]="Não Prenha",Tabela13[[#This Row],[E.C.C. IA]],"-") -> - | U39: =IF(Tabela13[[#This Row],[Diagnóstico]]="Não Prenha",Tabela13[[#This Row],[Raça IA]],"-") -> - | W39: =Tabela13[[#This Row],[Categoria]] -> 0 | AB39: =IF(P39="","",SUM(P39+295)) | AE39: =IF(Tabela1312[[#This Row],[Diagnóstico]]="Não Prenha ",Tabela13[[#This Row],[Vaca]],"-") -> - | AK39: =Tabela13[[#This Row],[Categoria]] -> 0 | AP39: =IF(AD39="","",SUM(AD39+295))
N40: =IF(B40="","",SUM(B40+295)) | Q40: =IF(Tabela13[[#This Row],[Diagnóstico]]="Não Prenha",Tabela13[[#This Row],[Vaca]],"-") -> - | R40: =IF(Tabela13[[#This Row],[Diagnóstico]]="Não Prenha",Tabela13[[#This Row],[E.C.C DG]],"-") -> - | T40: =IF(Tabela13[[#This Row],[Diagnóstico]]="Não Prenha",Tabela13[[#This Row],[E.C.C. IA]],"-") -> - | U40: =IF(Tabela13[[#This Row],[Diagnóstico]]="Não Prenha",Tabela13[[#This Row],[Raça IA]],"-") -> - | W40: =Tabela13[[#This Row],[Categoria]] -> 0 | AB40: =IF(P40="","",SUM(P40+295)) | AE40: =IF(Tabela1312[[#This Row],[Diagnóstico]]="Não Prenha ",Tabela13[[#This Row],[Vaca]],"-") -> - | AK40: =Tabela13[[#This Row],[Categoria]] -> 0 | AP40: =IF(AD40="","",SUM(AD40+295))
...

Sheet Lote 02
A1: Lote | B1: Data IA | C1: Vaca | D1: E.C.C DG | E1: Diagnóstico | F1: E.C.C. IA | G1: Raça IA | H1: CIO | I1: Categoria | J1: Touro | K1: Partida | L1: Inseminador | M1: Observação | N1: Previsão de Parto | P1: Data IA | Q1: Vaca | R1: E.C.C DG | S1: Diagnóstico | T1: E.C.C. IA | U1: Raça IA | V1: CIO | W1: Categoria | X1: Touro | Y1: Partida | Z1: Inseminador | AA1: Observação | AB1: Previsão de Parto | AD1: Data IA | AE1: Vaca | AF1: E.C.C DG | AG1: Diagnóstico | AH1: E.C.C. IA | AI1: Raça IA | AJ1: CIO | AK1: Categoria | AL1: Touro | AM1: Partida | AN1: Inseminador | AO1: Observação | AP1: Previsão de Parto
A2: Novilhas | B2: 45977 | C2: 1 | E2: Não Prenha | F2: 3 | J2: Vagalume | K2: 45245 | L2: Raimundo | M2: cl | N2: =IF(B2="","",SUM(B2+295)) -> 46272 | P2: 46032 | Q2: =IF(Tabela1336[[#This Row],[Diagnóstico]]="Não Prenha",Tabela1336[[#This Row],[Vaca]],"-") -> 1 | R2: =IF(Tabela1336[[#This Row],[Diagnóstico]]="Não Prenha",Tabela1336[[#This Row],[E.C.C DG]],"-") -> 0 | T2: =IF(Tabela1336[[#This Row],[Diagnóstico]]="Não Prenha",Tabela1336[[#This Row],[E.C.C. IA]],"-") -> 3 | U2: =IF(Tabela1336[[#This Row],[Diagnóstico]]="Não Prenha",Tabela1336[[#This Row],[Raça IA]],"-") -> 0 | W2: =Tabela1336[[#This Row],[Categoria]] -> 0 | X2: VAGALUME | Y2: 45210 | AB2: =IF(P2="","",SUM(P2+295)) -> 46327 | AE2: =IF(Tabela131247[[#This Row],[Diagnóstico]]="Não Prenha ",Tabela1336[[#This Row],[Vaca]],"-") -> - | AK2: =Tabela1336[[#This Row],[Categoria]] -> 0 | AP2: =IF(AD2="","",SUM(AD2+295))
A3: Novilhas | B3: 45977 | C3: 6 | E3: Não Prenha | F3: 3 | J3: Vagalume | K3: 45245 | L3: Raimundo | M3: cl/ uso 1 | N3: =IF(B3="","",SUM(B3+295)) -> 46272 | P3: 46032 | Q3: =IF(Tabela1336[[#This Row],[Diagnóstico]]="Não Prenha",Tabela1336[[#This Row],[Vaca]],"-") -> 6 | R3: =IF(Tabela1336[[#This Row],[Diagnóstico]]="Não Prenha",Tabela1336[[#This Row],[E.C.C DG]],"-") -> 0 | T3: =IF(Tabela1336[[#This Row],[Diagnóstico]]="Não Prenha",Tabela1336[[#This Row],[E.C.C. IA]],"-") -> 3 | U3: =IF(Tabela1336[[#This Row],[Diagnóstico]]="Não Prenha",Tabela1336[[#This Row],[Raça IA]],"-") -> 0 | W3: =Tabela1336[[#This Row],[Categoria]] -> 0 | AB3: =IF(P3="","",SUM(P3+295)) -> 46327 | AE3: =IF(Tabela131247[[#This Row],[Diagnóstico]]="Não Prenha ",Tabela1336[[#This Row],[Vaca]],"-") -> - | AK3: =Tabela1336[[#This Row],[Categoria]] -> 0 | AP3: =IF(AD3="","",SUM(AD3+295))
A4: Novilhas | B4: 45977 | C4: 8 | E4: Não Prenha | F4: 3 | J4: Vagalume | K4: 45245 | L4: Raimundo | M4: fl | N4: =IF(B4="","",SUM(B4+295)) -> 46272 | P4: 46032 | Q4: =IF(Tabela1336[[#This Row],[Diagnóstico]]="Não Prenha",Tabela1336[[#This Row],[Vaca]],"-") -> 8 | R4: =IF(Tabela1336[[#This Row],[Diagnóstico]]="Não Prenha",Tabela1336[[#This Row],[E.C.C DG]],"-") -> 0 | T4: =IF(Tabela1336[[#This Row],[Diagnóstico]]="Não Prenha",Tabela1336[[#This Row],[E.C.C. IA]],"-") -> 3 | U4: =IF(Tabela1336[[#This Row],[Diagnóstico]]="Não Prenha",Tabela1336[[#This Row],[Raça IA]],"-") -> 0 | W4: =Tabela1336[[#This Row],[Categoria]] -> 0 | X4: VAGALUME | Y4: 45210 | AB4: =IF(P4="","",SUM(P4+295)) -> 46327 | AE4: =IF(Tabela131247[[#This Row],[Diagnóstico]]="Não Prenha ",Tabela1336[[#This Row],[Vaca]],"-") -> - | AK4: =Tabela1336[[#This Row],[Categoria]] -> 0 | AP4: =IF(AD4="","",SUM(AD4+295))
A5: Novilhas | B5: 45977 | C5: 10 | E5: Prenha | F5: 3 | J5: Vagalume | K5: 45245 | L5: Raimundo | M5: cl | N5: =IF(B5="","",SUM(B5+295)) -> 46272 | Q5: =IF(Tabela1336[[#This Row],[Diagnóstico]]="Não Prenha",Tabela1336[[#This Row],[Vaca]],"-") -> - | R5: =IF(Tabela1336[[#This Row],[Diagnóstico]]="Não Prenha",Tabela1336[[#This Row],[E.C.C DG]],"-") -> - | T5: =IF(Tabela1336[[#This Row],[Diagnóstico]]="Não Prenha",Tabela1336[[#This Row],[E.C.C. IA]],"-") -> - | U5: =IF(Tabela1336[[#This Row],[Diagnóstico]]="Não Prenha",Tabela1336[[#This Row],[Raça IA]],"-") -> - | W5: =Tabela1336[[#This Row],[Categoria]] -> 0 | AB5: =IF(P5="","",SUM(P5+295)) | AE5: =IF(Tabela131247[[#This Row],[Diagnóstico]]="Não Prenha ",Tabela1336[[#This Row],[Vaca]],"-") -> - | AK5: =Tabela1336[[#This Row],[Categoria]] -> 0 | AP5: =IF(AD5="","",SUM(AD5+295))
A6: Novilhas | B6: 45977 | C6: 12 | E6: Não Prenha | F6: 3 | J6: Vagalume | K6: 45245 | L6: Raimundo | M6: cl | N6: =IF(B6="","",SUM(B6+295)) -> 46272 | P6: 46032 | Q6: =IF(Tabela1336[[#This Row],[Diagnóstico]]="Não Prenha",Tabela1336[[#This Row],[Vaca]],"-") -> 12 | R6: =IF(Tabela1336[[#This Row],[Diagnóstico]]="Não Prenha",Tabela1336[[#This Row],[E.C.C DG]],"-") -> 0 | T6: =IF(Tabela1336[[#This Row],[Diagnóstico]]="Não Prenha",Tabela1336[[#This Row],[E.C.C. IA]],"-") -> 3 | U6: =IF(Tabela1336[[#This Row],[Diagnóstico]]="Não Prenha",Tabela1336[[#This Row],[Raça IA]],"-") -> 0 | W6: =Tabela1336[[#This Row],[Categoria]] -> 0 | X6: VAGALUME | Y6: 45210 | AB6: =IF(P6="","",SUM(P6+295)) -> 46327 | AE6: =IF(Tabela131247[[#This Row],[Diagnóstico]]="Não Prenha ",Tabela1336[[#This Row],[Vaca]],"-") -> - | AK6: =Tabela1336[[#This Row],[Categoria]] -> 0 | AP6: =IF(AD6="","",SUM(AD6+295))
